Workbook
Name SegmentaçãodeDados_dia: #N/A
Name Usuario: #REF!

Sheet TD Painel
M2: Ano | N2: 2026 | R2: DiretoriaComercial | S2: DIRETORIA SPI
C3: ano | D3: 2026 | M3: canal_loja | N3: HOUSE | R3: Ano | S3: 2026
C4: nom_empreendimento | D4: (Vários itens) | M4: loja_ags | N4: NÃO
C5: diretoria | D5: DIRETORIA SPI | R5: DataBaseAssinaturaContratoSalesforce | S5: NomeGerente | T5: NomeCorretor | U5: NomeLoja | V5: # Vendas
C6: dia | D6: All | M6: DataBase | N6: regional_co | O6: nom_gerente | P6: TotalCorretores | Q6: TotalCorretoresMais10DiasSemLogin | R6: jan/2026 | T6: RAFAEL FERNANDES DECHICHI | U6: AGENTE DE SONHOS – EXTERIOR (NP 1) | V6: 3
M7: 01/01/2026 | N7: SENSIA CP | O7: IDELSO JOSE DA SILVA SANTOS DE ASSIS | P7: 19 | Q7: 16 | R7: jan/2026 | T7: WELLINGHTON CESAR PEREIRA FIGUEIREDO | U7: SENSIA IMOB CAMPINAS | V7: 9
C8: data_base | D8: canal_loja | E8: gerente | F8: supervisor_imob | G8: status_funil | H8: regional | I8: Funil_Real | M8: 01/01/2026 | N8: SENSIA RP | O8: DOUGLAS MENDES DE AGUIAR RODRIGUES | P8: 12 | Q8: 8 | R8: jan/2026 | S8: ADALTON JOSE DA SILVA | T8: AUDILAINE SANTANA DE SOUZA | U8: LOJA EQUIPE VIRTUAL BOTUCATU 1 | V8: 1
C9: 01/01/2026 | D9: AGS | G9: LEAD | H9: SP INT 2 | I9: 2 | M9: 01/01/2026 | N9: SP INT 1 | O9: ANDERSON COSTA CARAPETA | P9: 14 | Q9: 6 | R9: jan/2026 | S9: ADALTON JOSE DA SILVA | T9: CLEIDE APARECIDA RIBEIRA DA SILVA | U9: LOJA EQUIPE VIRTUAL BOTUCATU 1 | V9: 1
C10: 01/01/2026 | D10: AGS | G10: LEAD | H10: SP INT 4 | I10: 805 | M10: 01/01/2026 | N10: SP INT 1 | O10: EVANDRO DE BRITO | P10: 16 | Q10: 11 | R10: jan/2026 | S10: ADALTON JOSE DA SILVA | T10: CLEITON FRANCISCO XAVIER | U10: LOJA EQUIPE VIRTUAL BOTUCATU 1 | V10: 2
C11: 01/01/2026 | D11: AGS | G11: DOCUMENTAÇÃO ENVIADA | H11: SP INT 1 | I11: 2 | M11: 01/01/2026 | N11: SP INT 1 | O11: FABIO HENRIQUE VIDOTTI FERREIRA | P11: 2 | R11: jan/2026 | S11: ADALTON JOSE DA SILVA | T11: ISABELA CAROLINE LEMES | U11: LOJA EQUIPE VIRTUAL BOTUCATU 1 | V11: 1
C12: 01/01/2026 | D12: AGS | G12: DOCUMENTAÇÃO ENVIADA | H12: SP INT 2 | I12: 4 | M12: 01/01/2026 | N12: SP INT 1 | O12: PABLO MEDEIROS DA SILVA GADELHA | P12: 17 | Q12: 11 | R12: jan/2026 | S12: ADALTON JOSE DA SILVA | T12: JEAN CARLOS DE OLIVEIRA GOMES | U12: LOJA EQUIPE VIRTUAL BOTUCATU 1 | V12: 1
C13: 01/01/2026 | D13: AGS | G13: DOCUMENTAÇÃO ENVIADA | H13: SP INT 4 | I13: 48 | M13: 01/01/2026 | N13: SP INT 1 | O13: THAINA PIOLOGO MARQUES DE QUEIROZ | P13: 1 | R13: jan/2026 | S13: ADALTON JOSE DA SILVA | T13: JOAO PAULO CAVAZZANA | U13: LOJA EQUIPE VIRTUAL BOTUCATU 1 | V13: 1
C14: 01/01/2026 | D14: AGS | G14: DOCUMENTAÇÃO EM ANÁLISE | H14: SP INT 1 | I14: 1 | M14: 01/01/2026 | N14: SP INT 1 | O14: THAMIRES PEREIRA COSTA | P14: 19 | Q14: 5 | R14: jan/2026 | S14: ADALTON JOSE DA SILVA | T14: MARCOS ANTÔNIO GARCIA | U14: LOJA EQUIPE VIRTUAL BOTUCATU 1 | V14: 2
C15: 01/01/2026 | D15: AGS | G15: DOCUMENTAÇÃO EM ANÁLISE | H15: SP INT 2 | I15: 1 | M15: 01/01/2026 | N15: SP INT 1 | O15: TIAGO AUGUSTO DA COSTA | P15: 17 | Q15: 6 | R15: jan/2026 | S15: ADALTON JOSE DA SILVA | T15: ROSANGELA APARECIDA PINTO SIMÃO | U15: LOJA EQUIPE VIRTUAL BOTUCATU 1 | V15: 1
C16: 01/01/2026 | D16: AGS | G16: DOCUMENTAÇÃO EM ANÁLISE | H16: SP INT 4 | I16: 39 | M16: 01/01/2026 | N16: SP INT 2 | O16: DOMINIQUE DAMASO DE SALES | P16: 14 | Q16: 6 | R16: jan/2026 | S16: ADALTON JOSE DA SILVA | T16: SOLENE MATOS DE AQUINO | U16: LOJA EQUIPE VIRTUAL BOTUCATU 1 | V16: 1
C17: 01/01/2026 | D17: AGS | G17: DOCUMENTAÇÃO COM PENDÊNCIA | H17: SP INT 2 | I17: 3 | M17: 01/01/2026 | N17: SP INT 2 | O17: FLAVIANO DE SOUZA CORREA | P17: 15 | Q17: 6 | R17: jan/2026 | S17: ALEXANDRE FORMIGA NETO | T17: LEONARDO VICTOR DA SILVA | U17: EQUIPE CREDENCIADA JUNDIAI 2 | V17: 1
C18: 01/01/2026 | D18: AGS | G18: DOCUMENTAÇÃO COM PENDÊNCIA | H18: SP INT 4 | I18: 9 | M18: 01/01/2026 | N18: SP INT 2 | O18: HEITOR NEVES MANCUZO | P18: 19 | Q18: 8 | R18: jan/2026 | S18: ALEXANDRE FORMIGA NETO | T18: LUCIANA AMARAL ARAÚJO QUINTAL | U18: EQUIPE CREDENCIADA JUNDIAI 2 | V18: 2
C19: 01/01/2026 | D19: AGS | G19: CPF ANALISADO | H19: SP INT 1 | I19: 1 | M19: 01/01/2026 | N19: SP INT 2 | O19: RAFAEL MOLL RECUPERO | P19: 12 | Q19: 8 | R19: jan/2026 | S19: ALEXANDRE FORMIGA NETO | T19: PAULO ALEXANDRE JORGE | U19: EQUIPE CREDENCIADA JUNDIAI 2 | V19: 2
C20: 01/01/2026 | D20: AGS | G20: CPF ANALISADO | H20: SP INT 2 | I20: 1 | M20: 01/01/2026 | N20: SP INT 2 | O20: STEPHANE MASCARENHAS TEIXEIRA | P20: 13 | Q20: 11 | R20: jan/2026 | S20: ALEXANDRE FORMIGA NETO | T20: RUTH NUNES DOS SANTOS LIMA | U20: EQUIPE CREDENCIADA JUNDIAI 2 | V20: 1
C21: 01/01/2026 | D21: AGS | G21: CPF ANALISADO | H21: SP INT 4 | I21: 39 | M21: 01/01/2026 | N21: SP INT 3 | O21: ARMANDO DONIZETTI CUSTODIO | P21: 16 | Q21: 7 | R21: jan/2026 | S21: ALINE CRISTINA MORENO | T21: ALANA EMILY DE SOUZA BATISTA | U21: IMOB CAMPINAS 2 | V21: 1
C22: 01/01/2026 | D22: AGS | G22: CPF ANALISADO COM PENDÊNCIA | H22: SP INT 2 | I22: 1 | M22: 01/01/2026 | N22: SP INT 3 | O22: BRUNA PAULINO BENEDETTI | P22: 9 | Q22: 7 | R22: jan/2026 | S22: ALINE CRISTINA MORENO | T22: GUSTAVO GUINATTI VENTURINI | U22: IMOB CAMPINAS 1 | V22: 10
C23: 01/01/2026 | D23: AGS | G23: CPF ANALISADO COM PENDÊNCIA | H23: SP INT 4 | I23: 3 | M23: 01/01/2026 | N23: SP INT 3 | O23: DEIVES RODRIGO DA COSTA | P23: 17 | Q23: 10 | R23: jan/2026 | S23: ALINE CRISTINA MORENO | T23: LARISSA NEVES TEIXEIRA | U23: IMOB CAMPINAS 3 | V23: 8
C24: 01/01/2026 | D24: AGS | G24: CPF APROVADO | H24: SP INT 1 | I24: 1 | M24: 01/01/2026 | N24: SP INT 3 | O24: MAISA MUNIZ DA SILVA | P24: 7 | Q24: 3 | R24: jan/2026 | S24: ANA RAQUEL CANDIDO MARCHETI | T24: ANA LETICIA COTRIM ALONSO | U24: IMOB SÃO CARLOS | V24: 10
C25: 01/01/2026 | D25: AGS | G25: CPF APROVADO | H25: SP INT 2 | I25: 1 | M25: 01/01/2026 | N25: SP INT 3 | O25: PEDRO MORENO MARQUES | P25: 13 | Q25: 5 | R25: jan/2026 | S25: ANA RAQUEL CANDIDO MARCHETI | T25: BRUNA FRANCINE ARAUJO SCHULTZ | U25: LOJA IMOB PIRACICABA 2 | V25: 8
... C34: 01/01/2026 | D34: AGS | G34: GANHO | H34: SP INT 4 | I34: 29 | M34: 01/01/2026 | N34: SP INT 4 | O34: TIAGO ALVES CARVALHO COELHO | P34: 18 | Q34: 6 | R34: jan/2026 | S34: ANDERSON COSTA CARAPETA | T34: PAULO ABILIO QUEIROZ | U34: VIRTUAL CPS 3 | V34: 1
C35: 01/01/2026 | D35: AGS | E35: ANANIAS FERREIRA DE SANT ANA NETO | G35: LEAD | H35: SP INT 5 | I35: 2 | M35: 01/01/2026 | N35: SP INT 5 | O35: JEFERSON EDUARDO NUNES | P35: 17 | Q35: 13 | R35: jan/2026 | S35: ANDERSON KUBICA | T35: GABRIEL MACIEL RETAMEIRO | U35: IMOB BOTUCATU | V35: 18
C36: 01/01/2026 | D36: AGS | E36: ANANIAS FERREIRA DE SANT ANA NETO | G36: DOCUMENTAÇÃO ENVIADA | H36: SP INT 5 | I36: 1 | M36: 01/01/2026 | N36: SP INT 5 | O36: JOEL TALMIR POPOWSKI | P36: 11 | Q36: 5 | R36: jan/2026 | S36: ANDERSON KUBICA | T36: LARISSA DE SA MARQUES | U36: IMOB MARÍLIA | V36: 9
C37: 01/01/2026 | D37: AGS | E37: ANANIAS FERREIRA DE SANT ANA NETO | G37: DOCUMENTAÇÃO COM PENDÊNCIA | H37: SP INT 5 | I37: 1 | M37: 01/01/2026 | N37: SP INT 5 | O37: JULIO CESAR FERREIRA | P37: 16 | Q37: 7 | R37: jan/2026 | S37: ANDERSON KUBICA | T37: NATHALIE FERNANDA POMPIANO | U37: IMOB BAURU | V37: 2
C38: 01/01/2026 | D38: AGS | E38: ANANIAS FERREIRA DE SANT ANA NETO | G38: CPF ANALISADO COM PENDÊNCIA | H38: SP INT 5 | I38: 1 | M38: 01/01/2026 | N38: SP INT 5 | O38: WELLINGTON DAMIAO CATARUSSI | P38: 9 | Q38: 8 | R38: jan/2026 | S38: ANDERSON KUBICA | T38: RONIE SANTIAGO DA SILVA | U38: LOJA IMOB BAURU 2 | V38: 2
C39: 01/01/2026 | D39: AGS | E39: ANANIAS FERREIRA DE SANT ANA NETO | G39: CPF APROVADO COM PENDÊNCIA | H39: SP INT 5 | I39: 1 | M39: 01/01/2026 | N39: SP INT 6 | O39: ALEXANDRE FORMIGA NETO | P39: 10 | Q39: 1 | R39: jan/2026 | S39: ANDREA CRISTINA MATHEUS FRATI | T39: CARLOS ROBERTO DE OLIVEIRA FILHO | U39: HIBRIDA CREDENCIADA SOROCABA 2 | V39: 2
C40: 01/01/2026 | D40: AGS | E40: GUSTAVO PAULINO SILVA | G40: LEAD | H40: SP INT 4 | I40: 25 | M40: 01/01/2026 | N40: SP INT 6 | O40: ANDREA CRISTINA MATHEUS FRATI | P40: 8 | Q40: 5 | R40: jan/2026 | S40: ARMANDO DONIZETTI CUSTODIO | T40: BRUNO VINICIUS NEVES DA SILVA | U40: HIBRIDA CREDENCIADA LIMEIRA 1 | V40: 2
C41: 01/01/2026 | D41: AGS | E41: GUSTAVO PAULINO SILVA | G41: DOCUMENTAÇÃO ENVIADA | H41: SP INT 4 | I41: 20 | M41: 01/01/2026 | N41: SP INT 6 | O41: JACKSON DE ALMEIDA PIRES | P41: 17 | Q41: 14 | R41: jan/2026 | S41: ARMANDO DONIZETTI CUSTODIO | T41: CARLOS ALBERTO SOARES | U41: HIBRIDA CREDENCIADA LIMEIRA 1 | V41: 1
C42: 01/01/2026 | D42: AGS | E42: GUSTAVO PAULINO SILVA | G42: DOCUMENTAÇÃO EM ANÁLISE | H42: SP INT 4 | I42: 11 | M42: 01/01/2026 | N42: SP INT 6 | O42: MARCONE DA SILVA FERREIRA DE ANDRADE | P42: 4 | Q42: 3 | R42: jan/2026 | S42: ARMANDO DONIZETTI CUSTODIO | T42: CICERO FERREIRA DA SILVA | U42: HIBRIDA CREDENCIADA LIMEIRA 1 | V42: 2
C43: 01/01/2026 | D43: AGS | E43: GUSTAVO PAULINO SILVA | G43: DOCUMENTAÇÃO COM PENDÊNCIA | H43: SP INT 4 | I43: 7 | M43: 01/01/2026 | N43: SP INT 6 | O43: PHILLIPE CAMILLOTI GRACIANO | P43: 21 | Q43: 12 | R43: jan/2026 | S43: ARMANDO DONIZETTI CUSTODIO | T43: GABRIELA MARTINHO BARBOZA | U43: HIBRIDA CREDENCIADA LIMEIRA 1 | V43: 1
C44: 01/01/2026 | D44: AGS | E44: GUSTAVO PAULINO SILVA | G44: CPF ANALISADO | H44: SP INT 4 | I44: 15 | M44: 01/01/2026 | N44: SP INT 6 | O44: VANESSA CRISTINE PERES | P44: 15 | Q44: 10 | R44: jan/2026 | S44: BRENDA MANTOVANI CONTE | T44: CAMILA LEMOS GUIMARAES | U44: IMOB SOROCABA 3 | V44: 13
C45: 01/01/2026 | D45: AGS | E45: GUSTAVO PAULINO SILVA | G45: CPF ANALISADO COM PENDÊNCIA | H45: SP INT 4 | I45: 2 | M45: 01/02/2026 | N45: SENSIA CP | O45: IDELSO JOSE DA SILVA SANTOS DE ASSIS | P45: 18 | Q45: 15 | R45: jan/2026 | S45: BRENDA MANTOVANI CONTE | T45: DOUGLAS OLIVEIRA CONCEICAO | U45: IMOB SOROCABA 2 | V45: 4
C46: 01/01/2026 | D46: AGS | E46: GUSTAVO PAULINO SILVA | G46: CPF APROVADO | H46: SP INT 4 | I46: 3 | M46: 01/02/2026 | N46: SENSIA RP | O46: DOUGLAS MENDES DE AGUIAR RODRIGUES | P46: 17 | Q46: 10 | R46: jan/2026 | S46: BRENDA MANTOVANI CONTE | T46: JANINE SILVA GODOY | U46: IMOB ITU 1 | V46: 5
C47: 01/01/2026 | D47: AGS | E47: GUSTAVO PAULINO SILVA | G47: CPF APROVADO COM PENDÊNCIA | H47: SP INT 4 | I47: 1 | M47: 01/02/2026 | N47: SP INT 1 | P47: 8 | Q47: 3 | R47: jan/2026 | S47: BRENDA MANTOVANI CONTE | T47: JHULYANNE ALLYNE ADAO MAZIERE | U47: IMOB SOROCABA | V47: 6
C48: 01/01/2026 | D48: AGS | E48: GUSTAVO PAULINO SILVA | G48: CPF CONDICIONADO | H48: SP INT 4 | I48: 6 | M48: 01/02/2026 | N48: SP INT 1 | O48: ALEXANDRE MIRANDA DOS PASSOS | P48: 2 | Q48: 2 | R48: jan/2026 | S48: BRUNA PAULINO BENEDETTI | T48: SABRINA CRISTINA DIAS CYRINO | U48: LOJA VIRTUAL SAO CARLOS 02 | V48: 2
C49: 01/01/2026 | D49: AGS | E49: GUSTAVO PAULINO SILVA | G49: CPF CONDICIONADO COM PENDÊNCIA | H49: SP INT 4 | I49: 1 | M49: 01/02/2026 | N49: SP INT 1 | O49: ANDERSON COSTA CARAPETA | P49: 19 | Q49: 10 | R49: jan/2026 | S49: DAIANE CRISTINA JIRICO | T49: CARLA DIAS BORTOLO | U49: EQUIPE PRÓPRIA VIRTUAL ARARAQUARA 3 | V49: 2
...

Sheet Planilha2
U1: regionalcompleta | V1: (Vários itens)
A2: diretoria | B2: DIRETORIA SPI | E2: diretoria | F2: DIRETORIA SPI | U2: diretoria | V2: DIRETORIA SPI
A3: canal_loja | B3: HOUSE | E3: canal_loja | F3: IMOB | U3: canal_loja | V3: IMOB
A4: data_base | B4: 01/04/2026 | E4: data_base | F4: 01/04/2026 | U4: data_base | V4: 01/03/2026
A5: dia | B5: (Vários itens) | E5: dia | F5: (Vários itens) | U5: dia | V5: All
A7: Regional | B7: Equipe House | C7: CPF Anl. | G7: CPF Anl. | U7: nom_loja | V7: supervisor_imob | W7: regional | X7: status_funil | Y7: Funil_Real
A8: SP INT 1 | B8: TIAGO AUGUSTO DA COSTA | C8: 3 | E8: SP INT 1 | F8: LARISSA NEVES TEIXEIRA | G8: 4 | U8: EQUIPE CREDENCIADA IMOB ARACATUBA | Y8: 13
A9: SP INT 2 | B9: DOMINIQUE DAMASO DE SALES | C9: 7 | E9: SP INT 2 | F9: HENRIQUE NEVES GARBELLINI | G9: 15 | U9: IMOB ARARAQUARA | W9: SP INT 4 | X9: LEAD | Y9: 27
A10: SP INT 3 | B10: MAISA MUNIZ DA SILVA | C10: 4 | E10: SP INT 3 | F10: ANA LETICIA COTRIM ALONSO | G10: 5 | U10: IMOB ARARAQUARA | W10: SP INT 4 | X10: DOCUMENTAÇÃO ENVIADA | Y10: 22
A11: SP INT 4 | B11: ADALTON JOSE DA SILVA | C11: 9 | E11: SP INT 4 | F11: MORIEL PAULINO CARVALHO | G11: 5 | U11: IMOB ARARAQUARA | W11: SP INT 4 | X11: DOCUMENTAÇÃO EM ANÁLISE | Y11: 7
A12: SP INT 5 | B12: JOEL TALMIR POPOWSKI | C12: 3 | E12: SP INT 5 | F12: RODRIGO MONTEIRO LIMA | G12: 6 | U12: IMOB ARARAQUARA | W12: SP INT 4 | X12: DOCUMENTAÇÃO COM PENDÊNCIA | Y12: 13
A13: SP INT 6 | B13: ANDREA CRISTINA MATHEUS FRATI | C13: 9 | E13: SP INT 6 | F13: CAMILA LEMOS GUIMARAES | G13: 5 | U13: IMOB ARARAQUARA | W13: SP INT 4 | X13: CPF ANALISADO | Y13: 6
U14: IMOB ARARAQUARA | W14: SP INT 4 | X14: CPF ANALISADO COM PENDÊNCIA | Y14: 2
U15: IMOB ARARAQUARA | W15: SP INT 4 | X15: CPF APROVADO COM PENDÊNCIA | Y15: 2
U16: IMOB ARARAQUARA | W16: SP INT 4 | X16: REGISTRO | Y16: 7
G17: CPF Anl. | U17: IMOB ARARAQUARA 2 | V17: PRISCILLA CARDOSO FERREIRA | W17: SP INT 4 | X17: LEAD | Y17: 60
E18: SP INT 1 | F18: LARISSA NEVES TEIXEIRA | G18: 7 | U18: IMOB ARARAQUARA 2 | V18: PRISCILLA CARDOSO FERREIRA | W18: SP INT 4 | X18: DOCUMENTAÇÃO ENVIADA | Y18: 82
E19: SP INT 2 | F19: HENRIQUE NEVES GARBELLINI | G19: 9 | M19: CPF Anl. | R19: Qtd_CPF_Analisado | U19: IMOB ARARAQUARA 2 | V19: PRISCILLA CARDOSO FERREIRA | W19: SP INT 4 | X19: DOCUMENTAÇÃO EM ANÁLISE | Y19: 34
E20: SP INT 3 | F20: LUCIANO FERREIRA DA SILVA | G20: 3 | K20: SP INT 1 | L20: ANDERSON COSTA CARAPETA | M20: 4 | P20: SP INT 1 | Q20: LARISSA NEVES TEIXEIRA | R20: 6 | U20: IMOB ARARAQUARA 2 | V20: PRISCILLA CARDOSO FERREIRA | W20: SP INT 4 | X20: DOCUMENTAÇÃO COM PENDÊNCIA | Y20: 50
E21: SP INT 4 | F21: GABRIEL MACIEL RETAMEIRO | G21: 3 | K21: SP INT 2 | L21: FLAVIANO DE SOUZA CORREA | M21: 3 | P21: SP INT 2 | Q21: HENRIQUE NEVES GARBELLINI | R21: 19 | U21: IMOB ARARAQUARA 2 | V21: PRISCILLA CARDOSO FERREIRA | W21: SP INT 4 | X21: CPF ANALISADO | Y21: 47
E22: SP INT 5 | F22: RODRIGO MONTEIRO DE LIMA | G22: 1 | K22: SP INT 3 | P22: SP INT 3 | Q22: CAMILA MENDES FRANCISCO | R22: 6 | U22: IMOB ARARAQUARA 2 | V22: PRISCILLA CARDOSO FERREIRA | W22: SP INT 4 | X22: CPF ANALISADO COM PENDÊNCIA | Y22: 18
E23: SP INT 6 | F23: CAMILA LEMOS GUIMARAES | G23: 3 | K23: SP INT 4 | L23: TIAGO ALVES CARVALHO COELHO | M23: 6 | P23: SP INT 4 | Q23: GABRIEL MACIEL RETAMEIRO | R23: 8 | U23: IMOB ARARAQUARA 2 | V23: PRISCILLA CARDOSO FERREIRA | W23: SP INT 4 | X23: CPF APROVADO | Y23: 16
K24: SP INT 5 | L24: JEFERSON EDUARDO NUNES | M24: 4 | P24: SP INT 5 | Q24: VANESSA FERREIRA DE MORAES | R24: 4 | U24: IMOB ARARAQUARA 2 | V24: PRISCILLA CARDOSO FERREIRA | W24: SP INT 4 | X24: CPF APROVADO COM PENDÊNCIA | Y24: 8
K25: SP INT 6 | L25: JACKSON DE ALMEIDA PIRES | M25: 4 | P25: SP INT 6 | Q25: CAMILA LEMOS GUIMARAES | R25: 8 | U25: IMOB ARARAQUARA 2 | V25: PRISCILLA CARDOSO FERREIRA | W25: SP INT 4 | X25: CPF CONDICIONADO | Y25: 17
U26: IMOB ARARAQUARA 2 | V26: PRISCILLA CARDOSO FERREIRA | W26: SP INT 4 | X26: CPF CONDICIONADO COM PENDÊNCIA | Y26: 10
U27: IMOB ARARAQUARA 2 | V27: PRISCILLA CARDOSO FERREIRA | W27: SP INT 4 | X27: CONTRATO GERADO | Y27: 15
U28: IMOB ARARAQUARA 2 | V28: PRISCILLA CARDOSO FERREIRA | W28: SP INT 4 | X28: CONTRATO ASSINADO | Y28: 12
U29: IMOB ARARAQUARA 2 | V29: PRISCILLA CARDOSO FERREIRA | W29: SP INT 4 | X29: GANHO | Y29: 11
U30: IMOB ARARAQUARA 2 | V30: PRISCILLA CARDOSO FERREIRA | W30: SP INT 4 | X30: REPASSE | Y30: 12
U31: IMOB ARARAQUARA 2 | V31: PRISCILLA CARDOSO FERREIRA | W31: SP INT 4 | X31: REGISTRO | Y31: 9
U32: IMOB BAURU | V32: NATHALIE FERNANDA POMPIANO | W32: SP INT 4 | X32: LEAD | Y32: 11
U33: IMOB BAURU | V33: NATHALIE FERNANDA POMPIANO | W33: SP INT 4 | X33: DOCUMENTAÇÃO ENVIADA | Y33: 18
U34: IMOB BAURU | V34: NATHALIE FERNANDA POMPIANO | W34: SP INT 4 | X34: DOCUMENTAÇÃO EM ANÁLISE | Y34: 13
U35: IMOB BAURU | V35: NATHALIE FERNANDA POMPIANO | W35: SP INT 4 | X35: DOCUMENTAÇÃO COM PENDÊNCIA | Y35: 5
U36: IMOB BAURU | V36: NATHALIE FERNANDA POMPIANO | W36: SP INT 4 | X36: CPF ANALISADO | Y36: 14
U37: IMOB BAURU | V37: NATHALIE FERNANDA POMPIANO | W37: SP INT 4 | X37: CPF ANALISADO COM PENDÊNCIA | Y37: 3
... U285: LOJA - IMOB RIBEIRÃO PRETO 3 | V285: HENRIQUE NEVES GARBELLINI | W285: SP INT 2 | X285: REGISTRO | Y285: 6
U286: LOJA – IMOB RIBEIRÃO PRETO 4 | W286: SP INT 2 | X286: LEAD | Y286: 4
U287: LOJA – IMOB RIBEIRÃO PRETO 4 | W287: SP INT 2 | X287: DOCUMENTAÇÃO ENVIADA | Y287: 3
U288: LOJA – IMOB RIBEIRÃO PRETO 4 | W288: SP INT 2 | X288: DOCUMENTAÇÃO EM ANÁLISE | Y288: 2
...

Sheet Planilha1
B1: Todos | C1: SPI | E1: Definitivos | F1: SPI | H1: Supervisor | I1: SPI
B2: {=_xlfn.UNIQUE(#REF!)} -> #REF! | C2: =_xlfn.XLOOKUP(Planilha1!B2,#REF!,#REF!) -> #REF! | E2: HENRIQUE NEVES GARBELLINI | F2: SP INT 2 | H2: {=_xlfn._xlws.FILTER(_xlfn.ANCHORARRAY(B2), COUNTIF(E2:E30,_xlfn.ANCHORARRAY(B2)) = 0)} -> #REF! | I2: =_xlfn.XLOOKUP(H2,B:B,C:C) -> #REF!
C3: =_xlfn.XLOOKUP(Planilha1!B3,#REF!,#REF!) -> #REF! | E3: CAMILA REGINA MELCHIADES | F3: SP INT 2 | I3: =_xlfn.XLOOKUP(H3,B:B,C:C) -> #REF!
C4: =_xlfn.XLOOKUP(Planilha1!B4,#REF!,#REF!) -> #REF! | E4: VINICIUS VIEIRA FRANCISCO | F4: SP INT 4 | I4: =_xlfn.XLOOKUP(H4,B:B,C:C) -> #REF!
C5: =_xlfn.XLOOKUP(Planilha1!B5,#REF!,#REF!) -> #REF! | E5: LUCAS PEREIRA MIGUEL | F5: SP INT 2 | I5: =_xlfn.XLOOKUP(H5,B:B,C:C) -> #REF!
C6: =_xlfn.XLOOKUP(Planilha1!B6,#REF!,#REF!) -> #REF! | E6: CAMILA MENDES FRANCISCO | F6: SP INT 3 | I6: =_xlfn.XLOOKUP(H6,B:B,C:C) -> #REF!
C7: =_xlfn.XLOOKUP(Planilha1!B7,#REF!,#REF!) -> #REF! | E7: CAMILA LEMOS GUIMARAES | F7: SP INT 6 | I7: =_xlfn.XLOOKUP(H7,B:B,C:C) -> #REF!
C8: =_xlfn.XLOOKUP(Planilha1!B8,#REF!,#REF!) -> #REF! | E8: JANINE SILVA GODOY | F8: SP INT 6 | I8: =_xlfn.XLOOKUP(H8,B:B,C:C) -> #REF!
C9: =_xlfn.XLOOKUP(Planilha1!B9,#REF!,#REF!) -> #REF! | E9: JHULYANNE ALLYNE ADAO MAZIERE | F9: SP INT 6 | I9: =_xlfn.XLOOKUP(H9,B:B,C:C) -> #REF!
C10: =_xlfn.XLOOKUP(Planilha1!B10,#REF!,#REF!) -> #REF! | E10: ANA LETICIA COTRIM ALONSO | F10: SP INT 3 | I10: =_xlfn.XLOOKUP(H10,B:B,C:C) -> #REF!
C11: =_xlfn.XLOOKUP(Planilha1!B11,#REF!,#REF!) -> #REF! | E11: WANDERSON FERNANDO ALVES JUNIOR | F11: SP INT 3 | I11: =_xlfn.XLOOKUP(H11,B:B,C:C) -> #REF!
C12: =_xlfn.XLOOKUP(Planilha1!B12,#REF!,#REF!) -> #REF! | E12: GUSTAVO GUINATTI VENTURINI | F12: SP INT 1 | I12: =_xlfn.XLOOKUP(H12,B:B,C:C) -> #REF!
C13: =_xlfn.XLOOKUP(Planilha1!B13,#REF!,#REF!) -> #REF! | E13: ALINE RODRIGUES DA SILVA | F13: SP INT 5 | I13: =_xlfn.XLOOKUP(H13,B:B,C:C) -> #REF!
C14: =_xlfn.XLOOKUP(Planilha1!B14,#REF!,#REF!) -> #REF! | E14: RODRIGO PERES BORBA | F14: SP INT 1 | I14: =_xlfn.XLOOKUP(H14,B:B,C:C) -> #REF!
... C30: =_xlfn.XLOOKUP(Planilha1!B30,#REF!,#REF!) -> #REF! | E30: ARTHUR TEIXEIRA PEREIRA | F30: SP INT 4 | I30: =_xlfn.XLOOKUP(H30,B:B,C:C) -> #REF!
C31: =_xlfn.XLOOKUP(Planilha1!B31,#REF!,#REF!) -> #REF! | I31: =_xlfn.XLOOKUP(H31,B:B,C:C) -> #REF!
C32: =_xlfn.XLOOKUP(Planilha1!B32,#REF!,#REF!) -> #REF! | I32: =_xlfn.XLOOKUP(H32,B:B,C:C) -> #REF!
C33: =_xlfn.XLOOKUP(Planilha1!B33,#REF!,#REF!) -> #REF! | I33: =_xlfn.XLOOKUP(H33,B:B,C:C) -> #REF!
C34: =_xlfn.XLOOKUP(Planilha1!B34,#REF!,#REF!) -> #REF! | I34: =_xlfn.XLOOKUP(H34,B:B,C:C) -> #REF!
C35: =_xlfn.XLOOKUP(Planilha1!B35,#REF!,#REF!) -> #REF! | I35: =_xlfn.XLOOKUP(H35,B:B,C:C) -> #REF!
C36: =_xlfn.XLOOKUP(Planilha1!B36,#REF!,#REF!) -> #REF! | I36: =_xlfn.XLOOKUP(H36,B:B,C:C) -> #REF!
C37: =_xlfn.XLOOKUP(Planilha1!B37,#REF!,#REF!) -> #REF! | I37: =_xlfn.XLOOKUP(H37,B:B,C:C) -> #REF!
C38: =_xlfn.XLOOKUP(Planilha1!B38,#REF!,#REF!) -> #REF! | I38: =_xlfn.XLOOKUP(H38,B:B,C:C) -> #REF!
C39: =_xlfn.XLOOKUP(Planilha1!B39,#REF!,#REF!) -> #REF! | I39: =_xlfn.XLOOKUP(H39,B:B,C:C) -> #REF!
C40: =_xlfn.XLOOKUP(Planilha1!B40,#REF!,#REF!) -> #REF! | I40: =_xlfn.XLOOKUP(H40,B:B,C:C) -> #REF!
C41: =_xlfn.XLOOKUP(Planilha1!B41,#REF!,#REF!) -> #REF! | I41: =_xlfn.XLOOKUP(H41,B:B,C:C) -> #REF!
C42: =_xlfn.XLOOKUP(Planilha1!B42,#REF!,#REF!) -> #REF! | I42: =_xlfn.XLOOKUP(H42,B:B,C:C) -> #REF!
... C86: =_xlfn.XLOOKUP(Planilha1!B86,#REF!,#REF!) -> #REF! | I86: =_xlfn.XLOOKUP(H86,B:B,C:C) -> #REF!
C87: =_xlfn.XLOOKUP(Planilha1!B87,#REF!,#REF!) -> #REF!
C88: =_xlfn.XLOOKUP(Planilha1!B88,#REF!,#REF!) -> #REF!
C89: =_xlfn.XLOOKUP(Planilha1!B89,#REF!,#REF!) -> #REF!
C90: =_xlfn.XLOOKUP(Planilha1!B90,#REF!,#REF!) -> #REF!
C91: =_xlfn.XLOOKUP(Planilha1!B91,#REF!,#REF!) -> #REF!
C92: =_xlfn.XLOOKUP(Planilha1!B92,#REF!,#REF!) -> #REF!
C93: =_xlfn.XLOOKUP(Planilha1!B93,#REF!,#REF!) -> #REF!
C94: =_xlfn.XLOOKUP(Planilha1!B94,#REF!,#REF!) -> #REF!
C95: =_xlfn.XLOOKUP(Planilha1!B95,#REF!,#REF!) -> #REF!
C96: =_xlfn.XLOOKUP(Planilha1!B96,#REF!,#REF!) -> #REF!
C97: =_xlfn.XLOOKUP(Planilha1!B97,#REF!,#REF!) -> #REF!
C98: =_xlfn.XLOOKUP(Planilha1!B98,#REF!,#REF!) -> #REF!
...
